Workbook

Sheet Hoja1
A1: Padre_familia | B1: id_familia | C1: Familia | D1: origen | E1: Codigo | F1: descripcion | G1: nombre web | H1: descripcion corta | J1: unidad | K1: Saldo | L1: Precio Venta | M1: PCP | N1: Proveedor | O1: VARIABLE | P1: COLOR | Q1: METRAJE
A2: LIBRERÍA | B2: 355 | C2: LIBRERÍA | D2: P | E2: P355PAP13383-3 | F2: EST.CARTULINA METALICA 10 HJS 7 COL.23,8 X 31,9 | G2: =VLOOKUP(E2,Hoja2!A:E,2,FALSE) -> ESTUCHE CARTULINA METALICA 10 HOJAS 7 COLORES 23,8 X 31,9 CM | H2: =VLOOKUP(E2,Hoja2!A:C,3,FALSE) -> Estuche Cartulina Metálica 10 Hojas 7 Colores 23,8 X 31,9 cm -Producto Nacional | J2: C/U | K2: 1 | L2: 2320 | M2: 1165 | N2: LIBE
A3: LIBRERÍA | B3: 355 | C3: LIBRERÍA | D3: P | E3: P355ESC25372-3 | F3: FORRO PROARTE LIBRO TRANSPA.BOLSA 10un CAJA PDQ | G3: =VLOOKUP(E3,Hoja2!A:E,2,FALSE) -> FORRO PROARTE LIBRO TRANSPA.BOLSA 10un CAJA PDQ | H3: =VLOOKUP(E3,Hoja2!A:C,3,FALSE) -> Forro PROARTE College Trasparente Bolsa 10 unidad -Producto Nacional | J3: C/U | K3: 15 | L3: 2920 | M3: 1469 | N3: LIBE
A4: LIBRERÍA | B4: 355 | C4: LIBRERÍA | D4: P | E4: P355ESC25367-7 | F4: FORRO PROARTE UNIVER.COL.SURT.BOLS.10un CAJA PD | G4: =VLOOKUP(E4,Hoja2!A:E,2,FALSE) -> FORRO PROARTE UNIVER.COL.SURT.BOLS.10un CAJA PD | H4: =VLOOKUP(E4,Hoja2!A:C,3,FALSE) -> Forro Proarte Univer.Col.Surt.Bols.10Un Caja Pd \n-Producto Nacional | J4: C/U | K4: 20 | L4: 2700 | M4: 1360 | N4: LIBE
A5: ACCESORIOS | B5: 108 | C5: ACCESORIOS AUTOMOVILES | D5: P | E5: P108HKY6004 | F5: PULPO ARTESANAL 4 BRAZOS 0,6MT | G5: =VLOOKUP(E5,Hoja2!A:E,2,FALSE) -> #N/A | H5: =VLOOKUP(E5,Hoja2!A:C,3,FALSE) -> #N/A | J5: C/U | K5: 0 | L5: 6500 | M5: 3300 | N5: JMUÑ
A6: LIBRERÍA | B6: 355 | C6: LIBRERÍA | D6: P | E6: P355ESC13442-2 | F6: ROLLO FORRO AUTOADHESIVO 0,33 X 1,50 TRANSPARENTE | G6: =VLOOKUP(E6,Hoja2!A:E,2,FALSE) -> ROLLO FORRO AUTOADHESIVO 0,33 X 1,50 TRANSPARENTE | H6: =VLOOKUP(E6,Hoja2!A:C,3,FALSE) -> Rollo Forro Autoadhesivo 0,33 X 1,50 Transparente \n \n-Producto Nacional | J6: C/U | K6: 0 | L6: 1400 | M6: 705 | N6: LIBE
A7: LIBRERÍA | B7: 355 | C7: LIBRERÍA | D7: P | E7: P355ESC14329-4 | F7: ROLLO FORRO AUTOADHESIVO 0,45 X 1,50 TRANSPARENTE | G7: =VLOOKUP(E7,Hoja2!A:E,2,FALSE) -> ROLLO FORRO AUTOADHESIVO 0,45 X 1,50 TRANSPARENTE | H7: =VLOOKUP(E7,Hoja2!A:C,3,FALSE) -> Rollo Forro Autoadhesivo 0,45 X 1,50 Transparente \n \n-Producto Nacional | J7: C/U | K7: 0 | L7: 1940 | M7: 978 | N7: LIBE
A8: LIBRERÍA | B8: 355 | C8: LIBRERÍA | D8: P | E8: P355PIN13074-5 | F8: TEMPERA PROARTE 6 col FRASCO 15 CC | G8: =VLOOKUP(E8,Hoja2!A:E,2,FALSE) -> TEMPERA PROARTE 6 colores FRASCO 15 CC | H8: =VLOOKUP(E8,Hoja2!A:C,3,FALSE) -> Tempera PROARTE 6 colores Frasco 15 CC -Producto Nacional | J8: C/U | K8: 1 | L8: 1400 | M8: 705 | N8: LIBE
A9: LIBRERÍA | B9: 355 | C9: LIBRERÍA | D9: P | E9: P355PIN34024-3 | F9: TEMPERA PROARTE 12+2 UNIDADES 15 CC | G9: =VLOOKUP(E9,Hoja2!A:E,2,FALSE) -> TEMPERA PROARTE 12 colores +2 UNIDADES 15 CC | H9: =VLOOKUP(E9,Hoja2!A:C,3,FALSE) -> Tempera PROARTE 12 colores +2 Unidades15 CC -Producto Nacional | J9: C/U | K9: 0 | L9: 2160 | M9: 1087 | N9: LIBE
A10: HOGAR | B10: 353 | C10: DECORACIÓN | D10: P | E10: P353CEST601745 | F10: 3 UNDS CESTA DE YUTE LT-334A,3PCS | G10: =VLOOKUP(E10,Hoja2!A:E,2,FALSE) -> 3 Unds Cesta De Yute Lt-334A,3Pcs | H10: =VLOOKUP(E10,Hoja2!A:C,3,FALSE) -> set cesta de yute A- 25 x 18, B- 23 x 16, C- 20 x 14 cm 3 unidades | J10: C/U | K10: 0 | L10: 13780 | M10: 5790 | N10: JUYIN
A11: HOGAR | B11: 353 | C11: DECORACIÓN | D11: P | E11: P353CEST601746 | F11: 3 UNDS CESTA DE YUTE S022-27,3PCS | G11: =VLOOKUP(E11,Hoja2!A:E,2,FALSE) -> 3 Unds Cesta De Yute S022-27,3Pcs | H11: =VLOOKUP(E11,Hoja2!A:C,3,FALSE) -> set de 3 cesta tejida de yute decorativa y de organización en tres tamaños | J11: C/U | K11: 0 | L11: 17180 | M11: 7218 | N11: JUYIN
A12: HOGAR | B12: 353 | C12: DECORACIÓN | D12: P | E12: P353CEST600099 | F12: 3UNDS CESTA DE MADERA 5423C-3PCS | G12: =VLOOKUP(E12,Hoja2!A:E,2,FALSE) -> 3Unds Cesta De Madera 5423C-3Pcs | H12: =VLOOKUP(E12,Hoja2!A:C,3,FALSE) -> Caja de madera decorativa con terminaciones, 3 unidades distintas dimensiones A- 40 x 30 x 20 cm. B- 34 x 24 x 18 cm. y C- 28 x 18 x 17 cm. | J12: C/U | K12: 2 | L12: 49580 | M12: 20832 | N12: JUYIN
A13: HOGAR | B13: 353 | C13: DECORACIÓN | D13: P | E13: P353CEST600042 | F13: 3UNDS CESTA DE YUTE LT-327A,3 PCS | G13: =VLOOKUP(E13,Hoja2!A:E,2,FALSE) -> 3Unds Cesta De Yute Lt-327A,3 Pcs | H13: =VLOOKUP(E13,Hoja2!A:C,3,FALSE) -> set cesta de yute A- 32 x 8, B- 25 x 6, C- 20 x 4 cm 3 unidades | J13: C/U | K13: 1 | L13: 12780 | M13: 5370 | N13: JUYIN
... A17: ACCESORIOS | B17: 114 | C17: ACCESORIOS HOGAR - FERRETERIA (ASEO) | D17: P | E17: P114CO25190558 | F17: 9193 JARRA 1,4 lts GRANADA | G17: =VLOOKUP(E17,Hoja2!A:E,2,FALSE) -> 9193 Jarra 1,4 Lts Granada | H17: =VLOOKUP(E17,Hoja2!A:C,3,FALSE) -> Transforma tus momentos de compartir en experiencias excepcionales con la Jarra de Vidrio Allegra, una pieza de elegancia atemporal que combina estilo y funcionalidad de manera magistral. Desde reuniones familiares hasta encuentros con amigos, esta jarra se convierte en el complemento perfecto para servir tus bebidas con distinción. La Jarra de Vid | J17: C/U | K17: 0 | L17: 5690 | M17: 2634 | N17: INVER
A18: ABRAZADERAS | B18: 103 | C18: ABRAZADERA ALAMBRE GALVANIZADO | D18: P | E18: P103CAG001G | F18: ABRAZADERA ALAMBRE GALV ( 1) 1/8 1/4 | G18: =VLOOKUP(E18,Hoja2!A:E,2,FALSE) -> #N/A | H18: =VLOOKUP(E18,Hoja2!A:C,3,FALSE) -> #N/A | J18: C/U | K18: 0 | L18: 215 | M18: 74
A19: ABRAZADERAS | B19: 103 | C19: ABRAZADERA ALAMBRE GALVANIZADO | D19: P | E19: P103CAG002G | F19: ABRAZADERA ALAMBRE GALV ( 2) 1/4 3/8 | G19: =VLOOKUP(E19,Hoja2!A:E,2,FALSE) -> #N/A | H19: =VLOOKUP(E19,Hoja2!A:C,3,FALSE) -> #N/A | J19: C/U | K19: 0 | L19: 234 | M19: 80
A20: ABRAZADERAS | B20: 103 | C20: ABRAZADERA ALAMBRE GALVANIZADO | D20: P | E20: P103CAG003G | F20: ABRAZADERA ALAMBRE GALV ( 3) 3/8 1/2 | G20: =VLOOKUP(E20,Hoja2!A:E,2,FALSE) -> #N/A | H20: =VLOOKUP(E20,Hoja2!A:C,3,FALSE) -> #N/A | J20: C/U | K20: 0 | L20: 245 | M20: 85
A21: ABRAZADERAS | B21: 103 | C21: ABRAZADERA ALAMBRE GALVANIZADO | D21: P | E21: P103CAG004G | F21: ABRAZADERA ALAMBRE GALV ( 4) 1/2 5/8 | G21: =VLOOKUP(E21,Hoja2!A:E,2,FALSE) -> #N/A | H21: =VLOOKUP(E21,Hoja2!A:C,3,FALSE) -> #N/A | J21: C/U | K21: 0 | L21: 258 | M21: 89
A22: ABRAZADERAS | B22: 103 | C22: ABRAZADERA ALAMBRE GALVANIZADO | D22: P | E22: P103CAG005G | F22: ABRAZADERA ALAMBRE GALV ( 5) 5/8 3/4 | G22: =VLOOKUP(E22,Hoja2!A:E,2,FALSE) -> #N/A | H22: =VLOOKUP(E22,Hoja2!A:C,3,FALSE) -> #N/A | J22: C/U | K22: 0 | L22: 271 | M22: 93
A23: ABRAZADERAS | B23: 103 | C23: ABRAZADERA ALAMBRE GALVANIZADO | D23: P | E23: P103CAG006G | F23: ABRAZADERA ALAMBRE GALV ( 6) 7/8 1 | G23: =VLOOKUP(E23,Hoja2!A:E,2,FALSE) -> #N/A | H23: =VLOOKUP(E23,Hoja2!A:C,3,FALSE) -> #N/A | J23: C/U | K23: 0 | L23: 282 | M23: 97
A24: ABRAZADERAS | B24: 103 | C24: ABRAZADERA ALAMBRE GALVANIZADO | D24: P | E24: P103CAG007G | F24: ABRAZADERA ALAMBRE GALV ( 7) 1 1/8 1 1/4 | G24: =VLOOKUP(E24,Hoja2!A:E,2,FALSE) -> #N/A | H24: =VLOOKUP(E24,Hoja2!A:C,3,FALSE) -> #N/A | J24: C/U | K24: 0 | L24: 295 | M24: 101
A25: ABRAZADERAS | B25: 103 | C25: ABRAZADERA ALAMBRE GALVANIZADO | D25: P | E25: P103CAG008G | F25: ABRAZADERA ALAMBRE GALV ( 8) 1 3/8 1 1/2 | G25: =VLOOKUP(E25,Hoja2!A:E,2,FALSE) -> #N/A | H25: =VLOOKUP(E25,Hoja2!A:C,3,FALSE) -> #N/A | J25: C/U | K25: 0 | L25: 306 | M25: 106
A26: ABRAZADERAS | B26: 103 | C26: ABRAZADERA ALAMBRE GALVANIZADO | D26: P | E26: P103CAG009G | F26: ABRAZADERA ALAMBRE GALV ( 9) 1 5/8 1 3/4 | G26: =VLOOKUP(E26,Hoja2!A:E,2,FALSE) -> #N/A | H26: =VLOOKUP(E26,Hoja2!A:C,3,FALSE) -> #N/A | J26: C/U | K26: 0 | L26: 321 | M26: 111 | N26: PRIS
A27: ABRAZADERAS | B27: 103 | C27: ABRAZADERA ALAMBRE GALVANIZADO | D27: P | E27: P103CAG010G | F27: ABRAZADERA ALAMBRE GALV (10) 1 7/8 2 | G27: =VLOOKUP(E27,Hoja2!A:E,2,FALSE) -> #N/A | H27: =VLOOKUP(E27,Hoja2!A:C,3,FALSE) -> #N/A | J27: C/U | K27: 0 | L27: 339 | M27: 116
A28: ABRAZADERAS | B28: 102 | C28: ABRAZADERA ACERO INOXIDABLE ALTA PRESION | D28: P | E28: P102CAPZG | F28: ABRAZADERA ALTA PRESION 32-35mm | G28: =VLOOKUP(E28,Hoja2!A:E,2,FALSE) -> #N/A | H28: =VLOOKUP(E28,Hoja2!A:C,3,FALSE) -> #N/A | J28: C/U | K28: 0 | L28: 1823 | M28: 575
A29: ABRAZADERAS | B29: 102 | C29: ABRAZADERA ACERO INOXIDABLE ALTA PRESION | D29: P | E29: P102CAPAG | F29: ABRAZADERA ALTA PRESION 35-38mm | G29: =VLOOKUP(E29,Hoja2!A:E,2,FALSE) -> #N/A | H29: =VLOOKUP(E29,Hoja2!A:C,3,FALSE) -> #N/A | J29: C/U | K29: 0 | L29: 1829 | M29: 586
A30: ABRAZADERAS | B30: 102 | C30: ABRAZADERA ACERO INOXIDABLE ALTA PRESION | D30: P | E30: P102CAPBG | F30: ABRAZADERA ALTA PRESION 38-41mm | G30: =VLOOKUP(E30,Hoja2!A:E,2,FALSE) -> #N/A | H30: =VLOOKUP(E30,Hoja2!A:C,3,FALSE) -> #N/A | J30: C/U | K30: 0 | L30: 1836 | M30: 589
A31: ABRAZADERAS | B31: 102 | C31: ABRAZADERA ACERO INOXIDABLE ALTA PRESION | D31: P | E31: P102CAPCG | F31: ABRAZADERA ALTA PRESION 41-44mm | G31: =VLOOKUP(E31,Hoja2!A:E,2,FALSE) -> #N/A | H31: =VLOOKUP(E31,Hoja2!A:C,3,FALSE) -> #N/A | J31: C/U | K31: 0 | L31: 1845 | M31: 591
A32: ABRAZADERAS | B32: 102 | C32: ABRAZADERA ACERO INOXIDABLE ALTA PRESION | D32: P | E32: P102CAPMG | F32: ABRAZADERA ALTA PRESION 83-88mm | G32: =VLOOKUP(E32,Hoja2!A:E,2,FALSE) -> #N/A | H32: =VLOOKUP(E32,Hoja2!A:C,3,FALSE) -> #N/A | J32: C/U | K32: 0 | L32: 1964 | M32: 757
A33: ABRAZADERAS | B33: 104 | C33: ABRAZADERA BANDA ANGOSTA | D33: P | E33: P104CBA20G | F33: ABRAZADERA BANDA ANGOSTA (1) 7/8 - 1 1/8 | G33: =VLOOKUP(E33,Hoja2!A:E,2,FALSE) -> #N/A | H33: =VLOOKUP(E33,Hoja2!A:C,3,FALSE) -> #N/A | J33: C/U | K33: 0 | L33: 287 | M33: 96
A34: ABRAZADERAS | B34: 104 | C34: ABRAZADERA BANDA ANGOSTA | D34: P | E34: P104CBA1G | F34: ABRAZADERA BANDA ANGOSTA (3) 1 1/4 - 2 | G34: =VLOOKUP(E34,Hoja2!A:E,2,FALSE) -> #N/A | H34: =VLOOKUP(E34,Hoja2!A:C,3,FALSE) -> #N/A | J34: C/U | K34: 0 | L34: 333 | M34: 112
A35: ABRAZADERAS | B35: 105 | C35: ABRAZADERA CREMALLERA | D35: P | E35: P105ACMSAG | F35: ABRAZADERA CREMALLERA ( 1) 5/16 - 3/8 | G35: =VLOOKUP(E35,Hoja2!A:E,2,FALSE) -> #N/A | H35: =VLOOKUP(E35,Hoja2!A:C,3,FALSE) -> #N/A | J35: C/U | K35: 41 | L35: 224 | M35: 86
A36: ABRAZADERAS | B36: 105 | C36: ABRAZADERA CREMALLERA | D36: P | E36: P105ACFSG | F36: ABRAZADERA CREMALLERA ( 4) 5/8 - 7/8 | G36: =VLOOKUP(E36,Hoja2!A:E,2,FALSE) -> #N/A | H36: =VLOOKUP(E36,Hoja2!A:C,3,FALSE) -> #N/A | J36: C/U | K36: 0 | L36: 271 | M36: 92
A37: ABRAZADERAS | B37: 105 | C37: ABRAZADERA CREMALLERA | D37: P | E37: P105AC30G | F37: ABRAZADERA CREMALLERA ( 5) 3/4 - 7/8 (19-22 MM 3/0) | G37: =VLOOKUP(E37,Hoja2!A:E,2,FALSE) -> #N/A | H37: =VLOOKUP(E37,Hoja2!A:C,3,FALSE) -> #N/A | J37: C/U | K37: 77 | L37: 338 | M37: 130 | N37: PRIS
A38: ABRAZADERAS | B38: 105 | C38: ABRAZADERA CREMALLERA | D38: P | E38: P105AC20G | F38: ABRAZADERA CREMALLERA ( 6) 7/8 - 1 1/8 (22-28 MM 2/0) | G38: =VLOOKUP(E38,Hoja2!A:E,2,FALSE) -> #N/A | H38: =VLOOKUP(E38,Hoja2!A:C,3,FALSE) -> #N/A | J38: C/U | K38: 43 | L38: 352 | M38: 117 | N38: PRIS
A39: ABRAZADERAS | B39: 105 | C39: ABRAZADERA CREMALLERA | D39: P | E39: P105AC10G | F39: ABRAZADERA CREMALLERA ( 7) 1 - 1 1/4 (24-32 MM 1/0) | G39: =VLOOKUP(E39,Hoja2!A:E,2,FALSE) -> #N/A | H39: =VLOOKUP(E39,Hoja2!A:C,3,FALSE) -> #N/A | J39: C/U | K39: 82 | L39: 365 | M39: 141 | N39: PRIS
A40: ABRAZADERAS | B40: 105 | C40: ABRAZADERA CREMALLERA | D40: P | E40: P105ACOEG | F40: ABRAZADERA CREMALLERA ( 8) 1 1/4 - 1 3/4 (32-44 MM 0E) | G40: =VLOOKUP(E40,Hoja2!A:E,2,FALSE) -> #N/A | H40: =VLOOKUP(E40,Hoja2!A:C,3,FALSE) -> #N/A | J40: C/U | K40: 115 | L40: 375 | M40: 125 | N40: PRIS
A41: ABRAZADERAS | B41: 105 | C41: ABRAZADERA CREMALLERA | D41: P | E41: P105AC1G | F41: ABRAZADERA CREMALLERA ( 9) 1 1/4 - 2 (32-52 MM 1) | G41: =VLOOKUP(E41,Hoja2!A:E,2,FALSE) -> #N/A | H41: =VLOOKUP(E41,Hoja2!A:C,3,FALSE) -> #N/A | J41: C/U | K41: 32 | L41: 390 | M41: 150 | N41: PRIS
A42: ABRAZADERAS | B42: 105 | C42: ABRAZADERA CREMALLERA | D42: P | E42: P105AC1EG | F42: ABRAZADERA CREMALLERA (10) 1 5/8 - 2 1/4 (41-56 MM 1E) | G42: =VLOOKUP(E42,Hoja2!A:E,2,FALSE) -> #N/A | H42: =VLOOKUP(E42,Hoja2!A:C,3,FALSE) -> #N/A | J42: C/U | K42: 91 | L42: 409 | M42: 137 | N42: PRIS
A43: ABRAZADERAS | B43: 105 | C43: ABRAZADERA CREMALLERA | D43: P | E43: P105AC2G | F43: ABRAZADERA CREMALLERA (11) 2 - 2 1/2 (47-57 MM 2) | G43: =VLOOKUP(E43,Hoja2!A:E,2,FALSE) -> #N/A | H43: =VLOOKUP(E43,Hoja2!A:C,3,FALSE) -> #N/A | J43: C/U | K43: 97 | L43: 417 | M43: 139 | N43: PRIS
...

Sheet Hoja3
A1: PISOS GOMA EN ROLLO SIN TELA | B1: Por tipo de tráfico | C1: Diseño | D1: Uso Comercial e Industrial | E1: Uso Deportivo y Recreacional | F1: Uso Transporte y Logística | G1: Uso Residencial y Áreas Comunes
B2: Tránsito Ligero o Peatonal Espacios: Casas, oficinas pequeñas, logias, maleteros de autos particulares y salas de juego infantiles. Carga: Solo el caminar de personas, mascotas o muebles livianos. Espesor recomendado: 2 mm a 3 mm. Es flexible, fácil de cortar con cartonero y liviano para instalar. | C2: Diseño Estoperol (Monedas o Botones) Características: Superficie con círculos en relieve que ofrecen un excelente agarre multidireccional.Usos ideales: Pasillos comerciales, transporte público (buses y trenes), rampas de acceso y zonas de alto tráfico peatonal.Ventaja: Es el diseño antideslizante por excelencia y estéticamente el más moderno. | D2: Talleres mecánicos: Soportan el derrame de aceites, grasas y fluidos automotrices sin absorberlos. | E2: Gimnasios y zonas de pesas: Absorben los impactos de las mancuernas y protegen la estructura del suelo. | F2: Pisos de buses y furgones: Recubren el suelo de vehículos de pasajeros para evitar resbalones los días de lluvia. | G2: Garajes domésticos: Permiten estacionar el auto protegiendo el radier de manchas de aceite difíciles de sacar.
B3: Tránsito Moderado o Comercial Espacios: Pasillos comerciales, gimnasios de entrenamiento funcional, furgones de reparto y garajes domésticos. Espesor recomendado: 3 mm a 5 mm. Ofrece un buen equilibrio entre amortiguación de impactos y resistencia al desgaste diario. Carga: Tránsito continuo de personas, carros de mano livianos, uso de mancuernas medianas y estacionamiento de vehículos comerciales. | C3: Diseño Acanalado (Estriado o Americano) Características: Líneas paralelas en relieve que corren a lo largo del rollo.Usos ideales: Cajas de camiones, pick-ups de camionetas, pasillos angostos y zonas de entrada.Ventaja: Facilita el escurrimiento de líquidos y permite canalizar la suciedad o el agua hacia los extremos. | D3: Fábricas y líneas de producción: Aíslan el frío del suelo y amortiguan la vibración de las maquinarias. | E3: Centros de crossfit: Ofrecen una superficie antideslizante para evitar caídas durante entrenamientos intensos. | F3: Maleteros y pick-ups: Protegen la lata de camionetas y autos del roce de la carga. | G3: Logias y lavaderos: Al ser impermeables, resisten la humedad constante y las salpicaduras de detergente.
B4: Tránsito Pesado o Industrial Espacios: Zonas de crossfit con caída libre de barras, talleres mecánicos pesados, cajas de camiones de carga y fábricas.Carga: Maquinaria pesada, arrastre de pallets, caída de herramientas pesadas y vehículos de gran tonelaje.Espesor recomendado: 5 mm a 8 mm (o más). Absorbe impactos severos, evita que se rompa el suelo base y aísla ruidos y vibraciones extremas. | C4: Diseño Liso Características: Superficie totalmente plana, sin texturas ni relieves.Usos ideales: Talleres mecánicos, laboratorios o áreas de ensamblaje donde se trabaja con piezas muy pequeñas.Ventaja: Es el más fácil de barrer, limpiar y fregar, ya que no acumula polvo ni grasa en las uniones. | D4: Pasillos de alto tráfico: Resisten el tránsito constante de personas y carros de carga ligera. | E4: Zonas de juegos infantiles: Amortiguan golpes y caídas de niños, siendo fáciles de limpiar de restos de comida o líquidos. | F4: Cajas de camiones: Evitan que la mercadería se deslice bruscamente durante el trayecto. | G4: Rampas y accesos: Se instalan en zonas inclinadas exteriores para transformarlas en superficies peatonales seguras. [1]
C5: Diseño Diamantado (Semilla de Melón) Características: Relieves en forma de rombos cruzados que imitan a las planchas metálicas industriales.Usos ideales: Talleres industriales, rampas de carga pesada y zonas exteriores resbaladizas.Ventaja: Ofrece la máxima tracción para calzado industrial y ruedas de maquinaria | D5: Bodegas y almacenes: Protegen el suelo de concreto contra la caída de herramientas u objetos pesados.
A6: EMPAQUETADURA POR ROLLO NR/SBR SIN TELA | B6: Límites técnicos de temperatura y presión | C6: Contacto con algún químico, combustible o aceite | D6: Uso en Fabricación de Juntas y Sellado | E6: Uso Protección y Amortiguación Industrial | F6: Uso Raspadores y Limpieza | G6: Uso Aislamiento General
B7: Rango de Temperatura Temperatura de trabajo: -20 °C hasta +70 °C (máximo continuo).Picos intermitentes: Puede tolerar hasta +80 °C por periodos muy cortos. Comportamiento: Si se supera este límite, la goma se reseca, se endurece y pierde su elasticidad, rompiendo el sello hermético. | C7: Aceites, Combustibles y Derivados del Petróleo Comportamiento: NO resiste. Efecto: El contacto con gasolina, petróleo diésel, aceites de motor, fluidos hidráulicos o grasas minerales disuelve los enlaces del SBR. La goma se hincha, se ablanda como chicle y se destruye rápidamente, perdiendo toda capacidad de sellado. Alternativa: Si tu aplicación involucra estos fluidos, debes usar Caucho Nitrilo (NBR). | D7: Juntas para bridas de agua: Sellado seguro en tuberías de agua fría, agua caliente (temperaturas moderadas) y fluidos no corrosivos. | E7: Cortinas protectoras: Cortinas de goma en cabinas de granallado o arenado para resistir la abrasión del impacto. | F7: Hojas de raspadores: Gomas para barredoras industriales o maquinaria de despeje de nieve y lodo. | G7: Aislantes de contacto: Barreras para evitar el contacto directo entre metales (corrosión galvánica) en estructuras livianas.
B8: Rango de Presión Restricción por espesor: A mayor espesor de la empaquetadura, menor es su resistencia a la presión, ya que el material tiende a "escupirse" o deformarse hacia afuera de la brida. Comportamiento: Al no tener tela interior, carece de resistencia estructural contra la deformación por aplastamiento o por el empuje de fluidos a alta presión. | C8: Ácidos y Químicos Fuertes Comportamiento: Resistencia baja a nula. Efecto: Los ácidos concentrados (como el sulfúrico o clorhídrico), solventes (diluyente, acetona) y químicos oxidantes degradan y queman el material de forma inmediata. Alternativa: Para químicos agresivos, se debe utilizar EPDM (para ácidos diluidos) o Viton (FKM) (para químicos severos y alta temperatura). | D8: Gasquetes industriales: Fabricación de empaquetaduras a medida para estanques de almacenamiento de fluidos neutros. | E8: Apoyos antivibratorios: Almohadillas para colocar debajo de equipos ligeros, motores eléctricos o compresores para absorber ruidos. | F8: Rasquetas de limpieza: Tiras de goma flexibles utilizadas para escurrir grandes volúmenes de líquidos en plantas procesadoras. | G8: Cubiertas protectoras: Tapas provisionales para proteger hilos de flanges o uniones mecánicas durante trabajos de mantenimiento.
C9: Fluidos Compatibles (Uso Seguro) Agua: Excelente resistencia a agua dulce, agua salada, aguas servidas y soluciones acuosas diluidas. Aire y Gases Inertes: Ideal para sellar sistemas de paso de aire comprimido a baja presión, nitrógeno o dióxido de carbono. Alcoholes y Álcalis Débiles: Soporta el contacto con alcoholes comerciales y soluciones de limpieza muy diluidas. | D9: Sellos de compuertas: Juntas de estanqueidad para ductos de ventilación, escotillas ligeras y cajas de inspección. | E9: Faldones para cintas transportadoras: Guías laterales (placas de desgaste) que contienen el material transportado sin dañar la banda en movimiento.
A10: PISOS NOMAD | B10: Tipo de Suelo Instalación | C10: Zona de Instalación | D10: Uso Accesos Principales y Entradas | E10: Uso Transporte y Vehículos | F10: Uso Zonas Húmedas y Áreas Deportivas | G10: Uso Industria y Áreas de Trabajo
B11: Sobre Hormigón Rugoso Instalación sin base (Exterior): Es la mejor opción. No requiere pegamento. La rugosidad del hormigón ayuda a que el piso Nomad no se deslice, y los poros permiten que el agua de lluvia corra libremente por debajo.Instalación con base (Techado) y pegado: Si necesitas pegarlo, la superficie rugosa consumirá mucho adhesivo. Debes aplicar un primer o sellador para concreto antes de poner el pegamento de doble contacto (Neoprén). Esto tapará los poros y evitará que el hormigón "se absorba" el pegamento. | C11: Exterior sin Techo (Exposición Directa a Lluvia y Sol) En esta zona, el objetivo principal es detener el barro grueso, las piedras y permitir que el agua drene para que el piso no flote ni se transforme en una piscina. El material correcto: Debes usar obligatoriamente un piso Nomad SIN BASE (abierto). Esto permite que el agua pase a través de los rulos hacia el suelo. Tipo de instalación: Se recomienda una instalación suelta (sin pegar). Al no llevar pegamento, puedes enrollar el piso fácilmente para limpiar con hidrolavadora el barro acumulado abajo. Fijación perimetral: Si la zona es muy ventosa o transitan carros pesados, se fija únicamente el borde superior (el lado por donde entra la gente) con perfiles metálicos atornillados al hormigón. El resto del rollo se deja libre para que drene el agua. | D11: Edificios corporativos: Se instalan en las puertas de entrada para mantener limpios los pisos interiores de mármol, porcelanato o madera. | E11: Cubre alfombras para autos: Se cortan a la medida del piso del vehículo. Su estructura atrapa las piedras, arena y barro de los zapatos, evitando que manchen el tapiz original. | F11: Bordes de piscinas: Los modelos sin base permiten que el agua drene hacia el suelo, ofreciendo una superficie antideslizante y segura para caminar descalzo. | G11: Pasillos de fábricas: Retienen virutas, polvillos metálicos o aserrín que los operarios transportan en sus botas de seguridad.
B12: Sobre Cerámica o Baldosa Instalación Suelta: Si el tránsito es bajo o medio, el piso Nomad con base de goma se adherirá muy bien gracias al peso del vinilo. No se deslizará fácilmente sobre la cerámica.Instalación Pegada (Alto Tráfico): Si hay cerámicas sueltas o quebradas, debes repararlas primero. Al aplicar el adhesivo de contacto, asegúrate de rellenar bien las líneas de fragüe para que queden al mismo nivel de la cerámica, evitando que con el tiempo se calque la forma de los cuadrados en la alfombra Nomad. | C12: Entrada Techada (Zona de Transición) Esta es la zona crítica donde el piso Nomad debe retener la humedad fina y el polvo que queda en los zapatos antes de pisar el suelo interior del edificio.El material correcto: Se utiliza un piso Nomad CON BASE de goma (cerrado). La base actúa como un contenedor que atrapa el agua y la suciedad, evitando que pasen al radier o baldosa inferior.Tipo de instalación: Depende del flujo de personas:Tráfico Alto (Edificios, Malls): Se debe pegar al 100% con adhesivo de doble contacto resistente a la humedad (o instalarlo suelto dentro de una fosa o rebaje en el piso). Esto evita que la alfombra se arrugue o se desplace con el frenado de los zapatos.Tráfico Medio/Bajo (Locales chicos, Casas): Se instala suelto. El propio peso de la base de goma y el calzado mantendrán el piso firme. | D12: Centros comerciales y malls: Soportan el flujo continuo de miles de personas diarias, reteniendo el polvo y el barro. | E12: Buses y transporte público: Se usan en las pisaderas o pasillos de entrada para evitar resbalones en días lluviosos. | F12: Camarines y duchas: Aíslan los pies del suelo húmedo, reduciendo el riesgo de caídas y la proliferación de hongos. | G12: Zonas de alto tráfico peatonal: Protegen los pisos base del desgaste prematuro causado por el roce constante.
B13: Sobre Pavimento Liso (Hormigón Afinador o Epóxico) Instalación Pegada: Requiere muy poca cantidad de adhesivo de doble contacto porque no hay porosidad. El agarre será inmediato y extremadamente firme.Precaución: El suelo debe estar completamente desengrasado. Si el pavimento liso tiene restos de ceras, aceites industriales o abrillantadores, el pegamento fallará. Se debe limpiar previamente con un desengrasante industrial o alcohol isopropílico. | D13: Hoteles y restaurantes: Evitan que la suciedad arruine la estética del lobby o las alfombras interiores. | F13: Saunas y spas: Resisten la humedad constante sin pudrirse ni generar malos olores. [1]
A14: PISOS PLANCHA GOMA | B14: PALMETA TÁCTIL DE GOMA NO VIDENTE | C14: PISO EN PLANCHA ESTOPEROL | D14: PISO PASTELON JUEGOS | E14: PISO PLANCHA ANTIDESLIZANTE | F14: PISO PLANCHA ANTIF/COCINA | G14: PISO PLANCHA GYM EPDM PUZZLE | H14: PISO GIMNASIO MIX
B15: Palmetas de Alerta o Precaución (Diseño de Botones / Estoperoles) Estas palmetas tienen relieve de círculos truncados. Su función es advertir sobre un peligro inminente, un cambio de nivel o una parada obligatoria.Bordes de andenes y estaciones: Indican el límite seguro antes de las vías en metros, trenes y terminales de buses.Cruces peatonales y esquinas: Se ubican justo antes de bajar a la calzada o calle para que el peatón se detenga.Inicio y término de escaleras o rampas: Avisan que comienza un cambio de nivel para evitar caídas.Frente a puertas de ascensores: Altan el área de acceso seguro al elevador. | C15: Uso Comercial y Edificios Públicos Entradas y accesos peatonales: Retiene el avance de la humedad de los zapatos en días lluviosos antes de ingresar a locales comerciales.Escaleras y rampas de acceso: Se instala en los peldaños y zonas inclinadas para asegurar el apoyo del pie y evitar caídas.Pasillos de alto tráfico: Ideal para centros médicos, oficinas públicas y colegios debido a su alta durabilidad al desgaste mecánico. | D15: Áreas Infantiles y de Recreación Zonas de juegos en plazas públicas: Se instalan bajo columpios, resbalines, rampas y juegos modulares donde los niños saltan o caen constantemente.Patios de jardines infantiles y colegios: Reemplazan el hormigón rugoso o el pasto natural por una superficie limpia, suave y libre de astillas o piedras.Zonas de juegos en condominios: Crean espacios seguros dentro de comunidades residenciales para el uso seguro de bicicletas pequeñas o triciclos. | E15: El piso en plancha antideslizante (fabricado comúnmente en caucho, goma o PVC) es un revestimiento modular diseñado para entregar la máxima tracción, estabilidad y seguridad en zonas propensas a resbalones, caídas o donde se requiere un tránsito firme. Al venir en formato de plancha (palmeta), ofrece un excelente soporte estructural, es muy resistente al desgaste pesado y permite cambiar piezas dañadas de forma independiente. Sus usos principales se dividen según el entorno: | F15: Zonas de Cocción y Calientes (Línea de Fuegos) Frente a cocinas, freidoras y hornos: Aíslan al cocinero del calor del suelo y resisten las salpicaduras de aceite hirviendo y grasas pesadas sin deformarse ni derretirse. | G15: Los pisos en plancha para gimnasio de caucho EPDM con sistema puzzle (encajables) son revestimientos de alta densidad diseñados específicamente para el entrenamiento deportivo de alta intensidad. Las chispas o pecas de colores que tienen estas palmetas son de caucho EPDM, un material que les otorga una mayor resistencia al desgaste, protección UV y evita que se desgranen con el tiempo. Su formato tipo "puzzle" permite un armado rápido, modular y sin necesidad de usar adhesivos químicos. Sus usos principales se dividen según las distintas zonas de entrenamiento: | H15: El piso de gimnasio MIX (también conocido como piso mixto) es un revestimiento técnico que combina dos tipos de caucho: una base amortiguadora de caucho SBR negro reciclado y una capa superior decorativa y ultra resistente de caucho EPDM virgen en formato de chispas o pecas de colores. Su uso principal es el alto tráfico deportivo y comercial, destacando por ofrecer una excelente relación precio-calidad, ya que entrega la resistencia del EPDM en la superficie donde se pisa, pero reduce costos utilizando SBR en la base. Sus aplicaciones específicas son:
B16: Palmetas de Guía o Dirección (Diseño Acanalado / Bastones) Estas palmetas tienen relieve de líneas rectas paralelas. Su función es señalar la ruta segura a seguir o un camino libre de obstáculos.Ejes de circulación en veredas: Crean pasillos peatonales accesibles en plazas, paseos públicos y calles céntricas.Guiado en grandes recintos: Conducen al usuario desde la entrada de un edificio público (malls, hospitales, municipalidades) hacia los mesones de atención, tótems informativos o ascensores.Pasillos de tránsito libre: Indican tramos largos y rectos donde no existen postes, escaños ni basureros con los que chocar. | C16: Transporte y Logística Montacargas y ascensores de carga: Soporta el peso y el movimiento giratorio de las ruedas sin deformarse.Estaciones de metro y terminales de buses: Delimita zonas de tránsito peatonal pesado y áreas de espera segura.Pasillos de aviones y trenes: Absorbe el ruido de las pisadas y ofrece una superficie firme durante el movimiento del vehículo. | D16: Uso Deportivo Ligero y Gimnasios Infantiles Muros de escalada (boulder) para niños: Absorben los impactos de las caídas de baja altura en zonas de iniciación deportiva.Pistas de psicomotricidad: Utilizados en centros de terapia infantil o salas de estimulación temprana para que los niños gateen, rueden y corran sin riesgo de moretones. | E16: Uso Industrial y Talleres Accesos principales y entradas: Retiene el agua y el barro de los zapatos en días lluviosos, protegiendo las zonas interiores.Escaleras y pasillos de alto tráfico: Se instala en los peldaños y descansos de hospitales, colegios y malls para evitar caídas masivas.Zonas de cajas y atención al público: Brinda comodidad al personal y delimita de forma segura las áreas de espera. | F16: Zonas de Lavado y Desengrase (Scullery) Frente a lavavajillas industriales y lavaplatos: Sus perforaciones permiten que el agua y el jabón drenen inmediatamente hacia la pileta del suelo, manteniendo los pies del operario elevados y secos, evitando resbalones críticos. | G16: Zonas de Peso Libre y Musculación Áreas de mancuernas pesadas: Absorben el fuerte impacto y el ruido cuando los usuarios dejan caer las mancuernas o discos al suelo.Jaulas de potencia y racks: Protegen la losa de hormigón estructural del edificio de las trizaduras causadas por las cargas extremas de sentadillas o press de banca. | H16: Zonas de Musculación y Máquinas de Selectorizadas Gimnasios en Casa (Home Gyms) Premium Salas de Cardio y Clases Grupales Recepciones, Pasillos y Tiendas Deportivas
C17: Uso Industrial y de Talleres Líneas de ensamblaje: Funciona como un piso de descanso para operarios que pasan muchas horas de pie, aislando el frío del concreto.Zonas de empaque y bodegaje: Protege el suelo base del arrastre de cajas o golpes por caídas de productos.Talleres mecánicos ligeros: Evita los resbalones por goteo de agua o humedad ambiental (para aceites pesados se requiere una versión específica de nitrilo). | D17: Uso Residencial y Terrazas Patios traseros particulares: Ideales para delimitar el sector donde se instala una cama elástica, una piscina estructural o una casa de juegos de plástico.Senderos de jardín: Permiten crear caminos suaves y antideslizantes que aíslan la humedad del pasto para el tránsito seguro de niños y adultos mayores. | E17: Transporte y Logística Montacargas y ascensores de carga: Soporta el peso y el torque de las ruedas sin romperse ni desplazarse.Estaciones de pasajeros y andenes: Delimita las zonas de tránsito peatonal continuo en terminales de buses o trenes.Talleres mecánicos automotrices: Evita resbalones por goteo de agua (para contacto con aceites pesados se utiliza una versión especial de nitrilo NBR). | F17: Áreas de Preparación y Producción (Cuarto Frío/Caliente) Mesones de picado y ensamblaje: Reducen drásticamente el cansancio, dolores lumbares y fatiga muscular de los maestros de cocina y ayudantes que pasan turnos de pie de 8 a 12 horas.Zonas de emplatado: Protegen la loza, vasos o utensilios que caen por accidente, evitando que se quiebren al impactar contra el piso de cerámica tradicional. | G17: Zonas de Crossfit y Levantamiento Olímpico (Weightlifting) Plataformas de levantamiento: Soportan las caídas libres de barras olímpicas cargadas desde la altura de los hombros o sobre la cabeza.Áreas de lanzamientos de balones (Slam Balls): Amortiguan el rebote de balones medicinales pesados, protegiendo tanto el balón como el suelo base.
C18: Uso Deportivo y Recreativo Zonas de recepción en gimnasios: Soporta el tráfico de deportistas con calzado rudo.Pasillos de camarines: Resiste el tránsito con pies húmedos ofreciendo una superficie segura y de rápido secado. | D18: Ventajas Técnicas clave de este formato Drenaje incorporado: La mayoría de los pastelones tienen canales inferiores que permiten que el agua de lluvia corra hacia los desagües, evitando charcos.Fácil recambio: Si una zona se gasta o se rompe (por ejemplo, justo debajo del columpio), se cambia únicamente la palmeta dañada sin alterar el resto del piso. | E18: Uso Deportivo y Áreas Húmedas Pasillos de camarines y duchas: Resiste el tránsito con pies húmedos en gimnasios o clubes deportivos, ofreciendo un secado rápido.Zonas de recepción y cardio: Soporta el movimiento constante de personas y el peso de trotadoras o bicicletas estáticas. | F18: Áreas de Almacenamiento y Cámaras Frías Cámaras de refrigeración: Funcionan como aislante térmico para que el frío del piso de la cámara no traspase el calzado del personal de bodega.Zonas de barras y despachos: Permiten un tránsito fluido y seguro para los garzones que entran y salen rápido de la cocina hacia el comedor. | G18: Salas de Cardio y Clases Dirigidas Bajo trotadoras, elípticas y spinning: Aíslan las vibraciones y el ruido de los motores de las máquinas, evitando que se traspasen a los pisos inferiores del edificio. También evitan que las máquinas se deslicen por el movimiento.Entrenamiento funcional y HIIT: Ofrecen una superficie antideslizante con un excelente agarre para zapatillas, ideal para hacer piques cortos, saltos al cajón o burpees sin riesgo de lesiones en las articulaciones.
A19: GRADAS ESCALA DE GOMA | B19: LUGAR DE INSTALACIÓN | C19: MATERIAL DE LA BASE DE LA ESCALERA (HORMIGÓN, METAL O MADERA) | D19: USO EDIFICIOS PÚBLICOS Y DE ALTO TRÁNSITO PEATONAL | E19: USOS INDUSTRIAS, FÁBRICAS Y TALLERES | F19: USO TRANSPORTE PÚBLICO E INFRAESTRUCTURA | G19: ÁREAS COMUNES RESIDENCIALES Y CONDOMINIOS
B20: El lugar de instalación (interior o exterior con lluvia) es el factor más importante para definir el tipo de goma y el pegamento químico que se debe utilizar para que las gradas no se despeguen ni se deslicen. | C20: Base de Hormigón (Cemento / Radier) Es la base más común, pero al ser porosa e irregular requiere la mayor preparación antes de instalar. Preparación: El hormigón debe estar completamente curado, seco y liso. Si tiene baches, hoyos o el canto (la nariz del peldaño) está picado, se debe reparar previamente con un mortero de reparación de alta resistencia. Hay que barrer muy bien para eliminar todo el polvo suelto. Pegamento adecuado:En interiores: Adhesivo de contacto (Neoprén) aplicado a doble cara.En exteriores con lluvia: Adhesivo de poliuretano (PU) de dos componentes o adhesivo híbrido, ya que la humedad del cemento suelta el neoprén. | D20: Escuelas y universidades: Previenen caídas masivas de estudiantes en zonas de escaleras durante los horarios de recreo o evacuación. Hospitales y clínicas: Ofrecen una superficie segura y amortiguada para pacientes con movilidad reducida, adultos mayores o personal de emergencia que se traslada rápido. Malls y centros comerciales: Protegen los bordes de los peldaños de concreto o cerámica del desgaste y picaduras causadas por el flujo constante de miles de personas. | E20: Escaleras de emergencia y vías de evacuación: Aseguran un escape rápido y sin resbalones en situaciones de pánico o cortes de luz. Acceso a plataformas de maquinaria: Aíslan al trabajador del frío del metal y evitan caídas causadas por calzado industrial húmedo o con restos de polvo seco. Bodegas y almacenes: Soportan el impacto del calzado rudo de los operarios que suben y bajan con carga manual pesada. | F20: Estaciones de metro y terminales de buses: Soportan el tránsito rudo y la fricción constante, resistiendo el agua de lluvia que los pasajeros arrastran en sus zapatos. Peldaños de buses y trenes: Se instalan en los accesos de los vehículos de pasajeros para evitar accidentes graves al subir o bajar los días de lluvia. | G20: Escaleras exteriores de edificios: Soportan la humedad ambiental y las heladas matinales, evitando que los peldaños se vuelvan resbaladizos. Accesos a subterráneos o estacionamientos: Delimitan visualmente cada peldaño gracias a sus diseños texturizados (usualmente con líneas acanaladas).
B21: Instalación en Escalera Interior En interiores, el foco está en la resistencia al desgaste, la facilidad de limpieza y que el adhesivo no emita olores tóxicos durante el montaje. Material recomendado: Se pueden usar gradas tanto de Caucho Sintético como de PVC de alta densidad. Tipo de adhesivo: Se utiliza adhesivo de contacto tradicional (tipo Neoprén) de base solvente, o idealmente adhesivos acrílicos base agua de bajo olor si el edificio está en funcionamiento (colegios u hospitales). Mantenimiento: Al estar protegidas del sol, las gradas no sufren decoloración ni resecamiento, por lo que su vida útil supera fácilmente los 10 años con un trapeado húmedo normal. | C21: Base de Metal (Fierro / Plancha Diamantada o Lisa) El metal no absorbe pegamento, por lo que el agarre depende de una superficie limpia y libre de óxido. Preparación: Si la escalera tiene pintura suelta u óxido, se debe pasar una escobilla de acero o esmeril hasta dejar el metal firme. Luego, se debe limpiar toda la superficie con alcohol isopropílico o diluyente para eliminar cualquier rastro de grasa o aceite protector del fierro. Pegamento adecuado: Se utiliza adhesivo de poliuretano (PU) en cartucho o adhesivos híbridos de alta resistencia. El neoprén tradicional no tiene buena vejez sobre superficies metálicas lisas sometidas a vibración o flexión al pisar.
B22: Instalación en Escalera Exterior (Expuesta a la Lluvia y Sol) En exteriores, el agua y los cambios de temperatura destruyen los pegamentos comunes, y la radiación UV quema el plástico de baja calidad. Material recomendado: Debes usar obligatoriamente Caucho Natural/Sintético (goma dura) con aditivos de protección UV. Evita el PVC económico en exteriores, ya que el sol lo cristaliza (se pone rígido) y la lluvia lo vuelve extremadamente resbaladizo. Diseño obligatorio: Debe tener estrías o canales profundos en la huella para que el agua de lluvia evacúe hacia los lados y la suela del zapato mantenga el contacto con la goma. Tipo de adhesivo (Crítico): NO utilices Neoprén común, ya que el agua de lluvia y la humedad del hormigón lo terminan soltando. Se debe instalar con adhesivo de poliuretano de dos componentes (PU) o adhesivos de montaje híbridos de alta resistencia para exteriores. Estos pegamentos sellan mecánicamente la grada al suelo y son 100% impermeables. | C22: Base de Madera La madera se mueve, se dilata con el calor y se contrae con el frío, por lo que el pegamento debe ser flexible. Preparación: La madera debe estar firme, sin crujidos ni tablas sueltas. Si tiene capas antiguas de cera, barniz o pintura brillante, se debe lijar profundamente hasta llegar a la madera porosa natural para que el pegamento penetre. Pegamento adecuado: Adhesivo de contacto de alta flexibilidad o adhesivos de montaje específicos para madera y goma. En zonas de alto tráfico, además del pegamento, se recomienda fijar la nariz de la grada con pequeños tornillos autorroscantes planos o corchetes industriales en los extremos para asegurar que la madera no escupa la goma al dilatarse.
A23: GRADAS ESCALA DE PVC | B23: LUGAR DE INSTALACIÓN | C23: MATERIAL DE LA BASE DE LA ESCALERA (HORMIGÓN, METAL O MADERA) | D23: USO EDIFICIOS PÚBLICOS Y DE ALTO TRÁNSITO PEATONAL | E23: USOS INDUSTRIAS, FÁBRICAS Y TALLERES | F23: USO TRANSPORTE PÚBLICO E INFRAESTRUCTURA | G23: ÁREAS COMUNES RESIDENCIALES Y CONDOMINIOS
B24: El lugar de instalación (interior o exterior con lluvia) es el factor más importante para definir el tipo de goma y el pegamento químico que se debe utilizar para que las gradas no se despeguen ni se deslicen. | C24: Base de Hormigón (Cemento / Radier) Es la base más común, pero al ser porosa e irregular requiere la mayor preparación antes de instalar. Preparación: El hormigón debe estar completamente curado, seco y liso. Si tiene baches, hoyos o el canto (la nariz del peldaño) está picado, se debe reparar previamente con un mortero de reparación de alta resistencia. Hay que barrer muy bien para eliminar todo el polvo suelto. Pegamento adecuado:En interiores: Adhesivo de contacto (Neoprén) aplicado a doble cara.En exteriores con lluvia: Adhesivo de poliuretano (PU) de dos componentes o adhesivo híbrido, ya que la humedad del cemento suelta el neoprén. | D24: Escuelas y universidades: Previenen caídas masivas de estudiantes en zonas de escaleras durante los horarios de recreo o evacuación. Hospitales y clínicas: Ofrecen una superficie segura y amortiguada para pacientes con movilidad reducida, adultos mayores o personal de emergencia que se traslada rápido. Malls y centros comerciales: Protegen los bordes de los peldaños de concreto o cerámica del desgaste y picaduras causadas por el flujo constante de miles de personas. | E24: Escaleras de emergencia y vías de evacuación: Aseguran un escape rápido y sin resbalones en situaciones de pánico o cortes de luz. Acceso a plataformas de maquinaria: Aíslan al trabajador del frío del metal y evitan caídas causadas por calzado industrial húmedo o con restos de polvo seco. Bodegas y almacenes: Soportan el impacto del calzado rudo de los operarios que suben y bajan con carga manual pesada. | F24: Estaciones de metro y terminales de buses: Soportan el tránsito rudo y la fricción constante, resistiendo el agua de lluvia que los pasajeros arrastran en sus zapatos. Peldaños de buses y trenes: Se instalan en los accesos de los vehículos de pasajeros para evitar accidentes graves al subir o bajar los días de lluvia. | G24: Escaleras exteriores de edificios: Soportan la humedad ambiental y las heladas matinales, evitando que los peldaños se vuelvan resbaladizos. Accesos a subterráneos o estacionamientos: Delimitan visualmente cada peldaño gracias a sus diseños texturizados (usualmente con líneas acanaladas).
B25: Instalación en Escalera Interior En interiores, el foco está en la resistencia al desgaste, la facilidad de limpieza y que el adhesivo no emita olores tóxicos durante el montaje. Material recomendado: Se pueden usar gradas tanto de Caucho Sintético como de PVC de alta densidad. Tipo de adhesivo: Se utiliza adhesivo de contacto tradicional (tipo Neoprén) de base solvente, o idealmente adhesivos acrílicos base agua de bajo olor si el edificio está en funcionamiento (colegios u hospitales). Mantenimiento: Al estar protegidas del sol, las gradas no sufren decoloración ni resecamiento, por lo que su vida útil supera fácilmente los 10 años con un trapeado húmedo normal. | C25: Base de Metal (Fierro / Plancha Diamantada o Lisa) El metal no absorbe pegamento, por lo que el agarre depende de una superficie limpia y libre de óxido. Preparación: Si la escalera tiene pintura suelta u óxido, se debe pasar una escobilla de acero o esmeril hasta dejar el metal firme. Luego, se debe limpiar toda la superficie con alcohol isopropílico o diluyente para eliminar cualquier rastro de grasa o aceite protector del fierro. Pegamento adecuado: Se utiliza adhesivo de poliuretano (PU) en cartucho o adhesivos híbridos de alta resistencia. El neoprén tradicional no tiene buena vejez sobre superficies metálicas lisas sometidas a vibración o flexión al pisar.
B26: Instalación en Escalera Exterior (Expuesta a la Lluvia y Sol) En exteriores, el agua y los cambios de temperatura destruyen los pegamentos comunes, y la radiación UV quema el plástico de baja calidad. Material recomendado: Debes usar obligatoriamente Caucho Natural/Sintético (goma dura) con aditivos de protección UV. Evita el PVC económico en exteriores, ya que el sol lo cristaliza (se pone rígido) y la lluvia lo vuelve extremadamente resbaladizo. Diseño obligatorio: Debe tener estrías o canales profundos en la huella para que el agua de lluvia evacúe hacia los lados y la suela del zapato mantenga el contacto con la goma. Tipo de adhesivo (Crítico): NO utilices Neoprén común, ya que el agua de lluvia y la humedad del hormigón lo terminan soltando. Se debe instalar con adhesivo de poliuretano de dos componentes (PU) o adhesivos de montaje híbridos de alta resistencia para exteriores. Estos pegamentos sellan mecánicamente la grada al suelo y son 100% impermeables. | C26: Base de Madera La madera se mueve, se dilata con el calor y se contrae con el frío, por lo que el pegamento debe ser flexible. Preparación: La madera debe estar firme, sin crujidos ni tablas sueltas. Si tiene capas antiguas de cera, barniz o pintura brillante, se debe lijar profundamente hasta llegar a la madera porosa natural para que el pegamento penetre. Pegamento adecuado: Adhesivo de contacto de alta flexibilidad o adhesivos de montaje específicos para madera y goma. En zonas de alto tráfico, además del pegamento, se recomienda fijar la nariz de la grada con pequeños tornillos autorroscantes planos o corchetes industriales en los extremos para asegurar que la madera no escupa la goma al dilatarse.
A27: PISOS PVC | B27: LUGAR DE INSTALACIÓN | C27: MATERIAL DE LA BASE | D27: PISO PVC DIAMANTADO | E27: PISO PVC ESTOPEROL | F27: PISO PVC TIPO WET | G27: PISO PVC TIPO CAMARÍN
B28: Para instalar correctamente pisos de PVC (tanto en rollo como en listones Click, LVT o SPC), es fundamental analizar el lugar de instalación, ya que la humedad, la temperatura y el sol directo influyen en el comportamiento del plástico.Los requerimientos técnicos y recomendaciones se dividen según las características del espacio: | C28: El éxito de la instalación de cualquier piso de PVC (ya sea en rollo, listones Click, SPC o LVT) depende al 100% del tipo de base o suelo actual donde se va a montar [LVT (PVC puro), SPC de alto tráfico]. Como el PVC es un material flexible y delgado, cualquier imperfección, humedad o desnivel de la base se terminará transmitiendo o "calcando" en la superficie.A continuación, te detallo los requisitos técnicos y la preparación necesaria según cada tipo de base: | D28: El piso de PVC diamantado (con diseño de "semilla de melón" o rombos en relieve) es un revestimiento plástico de alta resistencia diseñado específicamente para entregar la máxima tracción, seguridad y durabilidad en zonas propensas a resbalones. Al ser de PVC, ofrece un acabado moderno, es más liviano que la goma y resulta extremadamente fácil de limpiar. Sus usos principales se dividen por sectores: | E28: El piso de PVC diamantado (con diseño de "semilla de melón" o rombos en relieve) es un revestimiento plástico de alta resistencia diseñado específicamente para entregar la máxima tracción, seguridad y durabilidad en zonas propensas a resbalones. Al ser de PVC, ofrece un acabado moderno, es más liviano que la goma y resulta extremadamente fácil de limpiar. Sus usos principales se dividen por sectores: | F28: Principales Usos y Aplicaciones Este tipo de piso es ampliamente utilizado en entornos comerciales, industriales y residenciales, tales como: Áreas recreativas y deportivas: Bordes de piscinas, saunas, jacuzzis, spas y terrazas exteriores. Zonas sanitarias y vestuarios: Duchas públicas, camarines, baños de gimnasios, hospitales y clínicas. Rubro gastronómico e industrial: Cocinas industriales, bares, plantas de procesamiento de alimentos y laboratorios. Protección de superficies: Se usa también en el fondo de cajones, estantes o lavaplatos comerciales para amortiguar y proteger vajilla o cristalería. | G28: Principales Usos y Aplicaciones Este tipo de piso es ampliamente utilizado en entornos comerciales, industriales y residenciales, tales como: Áreas recreativas y deportivas: Bordes de piscinas, saunas, jacuzzis, spas y terrazas exteriores. Zonas sanitarias y vestuarios: Duchas públicas, camarines, baños de gimnasios, hospitales y clínicas. Rubro gastronómico e industrial: Cocinas industriales, bares, plantas de procesamiento de alimentos y laboratorios. Protección de superficies: Se usa también en el fondo de cajones, estantes o lavaplatos comerciales para amortiguar y proteger vajilla o cristalería.
B29: Espacios Interiores Secos (Habitaciones, Pasillos, Oficinas) Es el entorno ideal para cualquier tipo de piso de PVC. Al no haber variaciones extremas de temperatura, el material no sufre deformaciones [LVT (PVC puro)].Espacios comunes: Dormitorios, livings, comedores, pasillos, salas de clases y oficinas de plantas libres [LVT (PVC puro)].Formato recomendado: Pisos vinílicos SPC o LVT en listones (sistema Click) para un acabado estético de alta gama, o PVC en rollo si buscas una alternativa económica y de rápida instalación [LVT (PVC puro), SPC de alto tráfico].Ventaja: Máxima durabilidad. El material no se raya fácilmente y mantiene su color original por años. | C29: Base de Radier o Hormigón (Cemento) Es la base más común, pero requiere una revisión estricta antes de trabajar.Requisito crítico: El cemento debe estar 100% seco (mínimo 28 días de secado si es nuevo) y libre de porosidad extrema.Preparación: Si la superficie está rugosa o tiene grietas, es obligatorio aplicar un mortero autonivelante para dejar el suelo liso como un espejo. Si instalas PVC en rollo sobre un cemento rugoso, el pegamento no agarrará bien y el piso se romperá rápido.Formato ideal: Si el radier está bien nivelado, acepta tanto PVC en rollo (pegado) como listones SPC Click. | D29: Zonas Industriales, Talleres y Bodegas Pasillos de tránsito peatonal seguro: Ideal para delimitar rutas de caminata en fábricas y almacenes. Talleres eléctricos y salas de tableros: Al ser un material plástico, reduce el riesgo de conducción eléctrica estática en áreas técnicas de mantenimiento. Montacargas y cabinas de ascensores: Recubre el piso de elevadores de carga para evitar que las transpaletas, carros manuales o pallets se deslicen bruscamente. | E29: Zonas Industriales, Talleres y Bodegas Pasillos de tránsito peatonal seguro: Ideal para delimitar rutas de caminata en fábricas y almacenes. Talleres eléctricos y salas de tableros: Al ser un material plástico, reduce el riesgo de conducción eléctrica estática en áreas técnicas de mantenimiento. Montacargas y cabinas de ascensores: Recubre el piso de elevadores de carga para evitar que las transpaletas, carros manuales o pallets se deslicen bruscamente. | F29: Características y Beneficios Clave Diseño Drenante (Trama Abierta): Su estructura en forma de "S" u ondas caladas permite que el agua y los líquidos filtren inmediatamente hacia el suelo base. Evita la acumulación de charcos. Propiedades Higiénicas: Cuenta con tratamientos antimicóticos y antibacteriales. Impide la proliferación de hongos, moho y malos olores en ambientes constantemente mojados. Confort a Pie Descalzo: Su textura es suave y agradable al tacto. No se sobrecalienta excesivamente bajo el sol, protegiendo los pies de quemaduras. Alta Resistencia: Tolera la exposición directa a los rayos UV (no pierde el color fácilmente) y resiste el contacto con químicos de limpieza o cloro. Instalación Inmediata: Generalmente se comercializa en rollos (de espesores entre 5 mm). No requiere adhesivos ni mano de obra compleja; simplemente se desenrolla sobre la superficie existente (cemento, cerámica, etc.). | G29: Características y Beneficios Clave Diseño Drenante (Trama Abierta): Su estructura en forma de "S" u ondas caladas permite que el agua y los líquidos filtren inmediatamente hacia el suelo base. Evita la acumulación de charcos. Propiedades Higiénicas: Cuenta con tratamientos antimicóticos y antibacteriales. Impide la proliferación de hongos, moho y malos olores en ambientes constantemente mojados. Confort a Pie Descalzo: Su textura es suave y agradable al tacto. No se sobrecalienta excesivamente bajo el sol, protegiendo los pies de quemaduras. Alta Resistencia: Tolera la exposición directa a los rayos UV (no pierde el color fácilmente) y resiste el contacto con químicos de limpieza o cloro. Instalación Inmediata: Generalmente se comercializa en rollos (de espesores entre 5 mm). No requiere adhesivos ni mano de obra compleja; simplemente se desenrolla sobre la superficie existente (cemento, cerámica, etc.).
B30: Zonas Húmedas Interiores (Baños, Cocinas, Lavaderos) El PVC es 100% impermeable, lo que lo convierte en el sustituto perfecto para la cerámica tradicional en áreas expuestas al agua [LVT (PVC puro)].Espacios comunes: Cocinas residenciales, baños públicos y privados, logias y zonas de lavado [LVT (PVC puro)].Formato recomendado: Pisos SPC Click (ya que su alma de piedra caliza evita que el agua filtre entre las uniones) o PVC en rollo pegado, el cual crea una superficie continua y sellada [LVT (PVC puro), SPC de alto tráfico].Precaución: Aunque el piso no se daña con el agua, si queda una filtración debajo del piso, se pueden generar hongos en el hormigón. El suelo base debe estar completamente seco antes de montar el piso. | C30: Base de Cerámica o Baldosa Antigua Es muy común en remodelaciones rápidas para evitar demoler el piso anterior.Requisito crítico: Las cerámicas deben estar firmes y pegadas. Si hay palmetas sueltas, se deben retirar y rellenar el hueco.Preparación: La línea del fragüe (la unión entre cerámicas) crea un pequeño hundimiento. Si pones un PVC encima, con los meses esa cuadrícula se marcará en la superficie. Para evitarlo, se debe aplicar una pasta de revisión o tapaporos sobre toda la cerámica para rellenar las uniones y dejar el suelo liso.Formato ideal: El piso SPC Click es el mejor para este caso, ya que al ser más rígido disimula mejor las pequeñas imperfecciones que el PVC en rollo. | D30: Logística, Garajes y Furgones Maleteros de vehículos y pick-ups: Protege la lata de camionetas o furgones del roce diario de herramientas o cajas de reparto. Estacionamientos residenciales techados: Resiste el goteo ligero de fluidos del motor (agua, refrigerante) y protege el radier del desgaste por el giro de las ruedas al estacionar. | E30: Logística, Garajes y Furgones Maleteros de vehículos y pick-ups: Protege la lata de camionetas o furgones del roce diario de herramientas o cajas de reparto. Estacionamientos residenciales techados: Resiste el goteo ligero de fluidos del motor (agua, refrigerante) y protege el radier del desgaste por el giro de las ruedas al estacionar.
B31: Recintos Sanitarios e Industriales (Espacios de Alta Higiene) Zonas que requieren desinfección constante y donde no se permite la acumulación de suciedad en juntas.Espacios comunes: Clínicas, pabellones quirúrgicos, laboratorios, clínicas veterinarias y cocinas comerciales [LVT (PVC puro)].Formato recomendado: Piso de PVC en rollo homogéneo o conductivo, instalado obligatoriamente con soldadura al calor en las uniones y zócalo sanitario (curvatura que sube hacia la pared) | C31: Base de Madera, Terciado o Planchas de OSB Se encuentra habitualmente en segundos pisos o construcciones ligeras.Requisito crítico: La madera debe estar completamente firme, atornillada y sin "juego" o crujidos al caminar. El movimiento de la base quiebra las uniones del PVC.Preparación: Se deben lijar las uniones entre planchas de madera y tapar las cabezas de los tornillos o clavos con masilla elastomérica.Formato ideal: El piso vinílico Click (LVT o SPC) funciona excelente porque flota sobre la madera y absorbe mejor las micro-dilataciones de la estructura. | D31: Uso Comercial, Eventos y Exhibiciones Rampas y pendientes de acceso: Entrega un excelente agarre para el público en zonas inclinadas techadas. Escenarios y stands de ferias: Es muy utilizado en el montaje temporal de eventos debido a su atractiva estética industrial, rapidez de despliegue y resistencia al calzado rudo. Locales comerciales y discotecas: Su superficie impermeable permite trapear y limpiar de forma muy rápida los derramamientos de líquidos o tragos. | E31: Uso Comercial, Eventos y Exhibiciones Rampas y pendientes de acceso: Entrega un excelente agarre para el público en zonas inclinadas techadas. Escenarios y stands de ferias: Es muy utilizado en el montaje temporal de eventos debido a su atractiva estética industrial, rapidez de despliegue y resistencia al calzado rudo. Locales comerciales y discotecas: Su superficie impermeable permite trapear y limpiar de forma muy rápida los derramamientos de líquidos o tragos.
B32: Exteriores Sin Techo (Terrazas, Patios, Balcones Descubiertos) Los pisos de PVC NO se deben instalar en exteriores descubiertos.Efecto del sol: La radiación UV directa cristaliza y decolora el PVC. En pocos meses se pondrá rígido y se quebrará.Efecto de la temperatura: El calor extremo del sol directo hace que el plástico se dilate de forma masiva, levantando las uniones Click o creando globos si está pegado.Alternativa: Para zonas exteriores sin techo se debe usar WPC (Deck compuesto) o Palmetas de caucho/goma. | C32: Base de Piso Flotante o Alfombra Antigua Requisito crítico: NO se puede instalar encima.Preparación: Si tienes una alfombra o un piso flotante antiguo, debes retirarlos por completo antes de la instalación. La alfombra es una base blanda que romperá los clics del piso vinílico, y el piso flotante antiguo puede acumular humedad y pudrirse debajo del PVC. | D32: Áreas Comunes y del Hogar Logias y salas de lavado: Resiste la humedad constante, salpicaduras de agua y derrames de detergente sin deformarse.Descansos de escaleras: Evita resbalamientos en los giros de escaleras de alto flujo en colegios, institutos o casas particulares [Cruzeiro Gomas]. | E32: Áreas Comunes y del Hogar Logias y salas de lavado: Resiste la humedad constante, salpicaduras de agua y derrames de detergente sin deformarse.Descansos de escaleras: Evita resbalamientos en los giros de escaleras de alto flujo en colegios, institutos o casas particulares [Cruzeiro Gomas].
A33: ESPONJAS DIMENSIONADAS | B33: ESPONJAS DIMENSIONADAS CNA | C33: ESPONJA AUTOADHESIVA PVC | D33: ESPONJAS DIMENSIONADAS SBR | E33: ESPONJAS EN PLANCHA | F33: ESPONJAS RODON NEOPREN | G33: ESPONJAS RODON SBR
